Workbook
Name __sqn1: '[1]compte de res charge T5'!$N$42
Name __srn1: '[1]compte de res charge T5'!$L$43
Name __tqn1: '[1]T6 compte de resultat produit'!$I$22
Name __ttn1: '[1]T6 compte de resultat produit'!$O$24
Name _azn1: #REF!
Name _bkn1: #REF!
Name _bqn1: #REF!
Name _brn1: #REF!
Name _btn1: #REF!
Name _cin1: #REF!
Name _cpn1: #REF!
Name _cum3: '[1]BALANCE N'!$J$2:$J$1001
Name _dan1: #REF!
Name _dbn1: #REF!
Name _dcn1: #REF!
Name _ddn1: #REF!
Name _dfn1: #REF!
Name _dgn1: #REF!
Name _dhn1: #REF!
Name _din1: #REF!
Name _djn1: #REF!
Name _dkn1: #REF!
Name _dln1: #REF!
Name _dmn1: #REF!
Name _dnn1: #REF!
Name _dpn1: #REF!
Name _dqn1: #REF!
Name _drn1: #REF!
Name _dsn1: #REF!
Name _dtn1: #REF!
Name _rwn1: #REF!
Name _san1: '[1]compte de res charge T5'!$N$29
Name _scn1: '[1]compte de res charge T5'!$N$30
Name _sfn1: #REF!
Name _shn1: #REF!
Name _sln1: '[1]compte de res charge T5'!$N$38
Name _son1: #REF!
Name _sqn1: #REF!
Name _srn1: #REF!
Name _ssn1: #REF!
Name _tan1: #REF!
Name _tbn1: #REF!
Name _tcn1: #REF!
Name _tdn1: #REF!
Name _tfn1: '[1]T6 compte de resultat produit'!$O$14
Name _tgn1: #REF!
Name _thn1: #REF!
Name _tkn1: #REF!
Name _tln1: #REF!
Name _tnn1: #REF!
Name _Toc12343290: 'Tendances et prévisions'!$B$7
Name _tqn1: #REF!
Name _tsn1: #REF!
Name _ttn1: #REF!
Name _txn1: #REF!
Name _uan1: '[1]T6 compte de resultat produit'!$O$28
Name _ucn1: '[1]T6 compte de resultat produit'!$O$29
Name _uen1: '[1]T6 compte de resultat produit'!$O$31
Name _ufn1: #REF!
Name _ugn1: #REF!

Sheet Bilan
C2: Désignation de l'entité: | D2: ELESYST SA | P2: Exercice clos le 31/12/ | Q2: 2019
C3: Numéro d'identification: | D3: MO1779U7P00197 | P3: Durée (en mois): | Q3: 12
C4: *Colonnes G (BRUT), I (AMORT. Et DEPREC.), T(EXERCICE au 31/12/N) et V(EXERCICE au 31/12/N-1) / Cellules K43 à 48 à renseigner manuellement
A5: BILAN AU 31 DECEMBRE N
A7: REF | C7: ACTIF | E7: Note | G7: EXERCICE au 31/12/N | M7: EXERCICE | N7: REF | P7: PASSIF | R7: Note | T7: EXERCICE | V7: EXERICE
G8: BRUT | I8: AMORT. | K8: NET | M8: AU | T8: au | V8: au
I9: et | M9: 31/12/N-1 | T9: 31/12/N | V9: 31/12/N-1
I10: DEPREC. | M10: NET | T10: NET | V10: NET
A11: AD | C11: IMMOBILISATIONS INCORPORELLES | E11: 3
A12: AE | C12: Frais de développement et de prospection | G12: 150000 | K12: =G12-I12 -> 150000 | M12: 180000 | N12: CA | P12: Capital | R12: 13 | T12: 15000000 | V12: 15000000
A13: AF | C13: Brevets, licences, logiciels, et droits similaires | G13: 500000 | K13: =G13-I13 -> 500000 | M13: 650000 | N13: CB | P13: Apporteurs capital appelé | R13: 13
A14: AG | C14: Fonds commercial et droit au bail | G14: 780000 | K14: =G14-I14 -> 780000 | M14: 1000000 | N14: CD | P14: Primes liées sans capital social | R14: 14
A15: AH | C15: Autres immobilisations corporelles | K15: =G15-I15 -> 0 | N15: CE | P15: Ecarts de réévaluation | R15: 3e
A16: AI | C16: IMMOBILISATIONS CORPORELLES | E16: 3 | K16: =G16-I16 -> 0 | N16: CF | P16: Réserves indisponibles | R16: 14 | T16: 1500000 | V16: 1500000
A17: AJ | C17: Terrains (dont le Placement en Net …………/………….) | G17: 3000000 | K17: =G17-I17 -> 3000000 | M17: 3000000 | N17: CG | P17: Réserves libres | R17: 14 | T17: 2000000 | V17: 2000000
A18: AK | C18: Bâtiments (dont le Placement en Net …………/………….) | G18: 15000000 | K18: =G18-I18 -> 15000000 | M18: 16000000 | N18: CH | P18: Report à nouveau | R18: 14 | T18: 7500000 | V18: 6000000
A19: AL | C19: Aménagements, agencements et installations | G19: 3000000 | K19: =G19-I19 -> 3000000 | M19: 3500000 | N19: CJ | P19: Résultat net de l'exercice (bénéfice + ou perte -) | T19: 6000000 | V19: 5000000
A20: AM | C20: Matériel, mobilier, et actifs biologiques | G20: 3500000 | K20: =G20-I20 -> 3500000 | M20: 4000000 | N20: CL | P20: Subventions d'investissement | R20: 15
A21: AN | C21: Matériel de transport | K21: =G21-I21 -> 0 | N21: CM | P21: Provisions règlementaires | R21: 15
A22: AP | C22: Avances et acomptes versés sur immobilisations | E22: 3 | K22: =G22-I22 -> 0 | N22: CP | P22: TOTAL CAPITAUX PROPRES ET RESSOURCES ASSIMILEES | T22: =SUM(T12:T21) -> 32000000 | V22: =SUM(V12:V21) -> 29500000
A23: AQ | C23: IMMOBILISATIONS FINANCIERES | E23: 4 | K23: =G23-I23 -> 0 | N23: DA | P23: Emprunts et dettes financières diverses | R23: 16 | T23: 8000000 | V23: 10000000
A24: AR | C24: Titres de participation | K24: =G24-I24 -> 0 | N24: DB | P24: Dettes de location acquisition | R24: 16
A25: AS | C25: Autres immobilisations financières | K25: =G25-I25 -> 0 | N25: DC | P25: Provisions pour risques et charges | R25: 16
A26: AZ | C26: TOTAL ACTIF IMMOBILISE | G26: =SUM(G12:G25) -> 25930000 | I26: =SUM(I12:I25) -> 0 | K26: =G26-I26 -> 25930000 | M26: =SUM(M12:M25) -> 28330000 | N26: DD | P26: TOTAL DETTES FINANCIERES ET RESSOURCES ASSIMILEES | T26: =SUM(T23:T25) -> 8000000 | V26: =SUM(V23:V25) -> 10000000
A27: BA | C27: ACTIF CIRCULANT HAO | E27: 5 | K27: =G27-I27 -> 0 | N27: DF | P27: TOTAL RESSOURCES STABLES | T27: =T22+T26 -> 40000000 | V27: =V22+V26 -> 39500000
A28: BB | C28: STOCKS ET ENCOURS | E28: 6 | K28: =G28-I28 -> 0 | N28: DH | P28: Dettes circulantes HAO | R28: 5 | T28: 3000000 | V28: 2500000
A29: BG | C29: CREANCES ET EMPLOIS ASSIMILES | K29: =G29-I29 -> 0 | N29: DI | P29: Clients, avances reçues | R29: 7
A30: BH | C30: Fournisseurs avances versées | E30: 17 | G30: 1500000 | K30: =G30-I30 -> 1500000 | M30: 1000000 | N30: DJ | P30: Fournisseurs d'exploitation | R30: 17 | T30: 2000000 | V30: 1500000
A31: BI | C31: Clients | E31: 7 | G31: 3000000 | K31: =G31-I31 -> 3000000 | M31: 2500000 | N31: DK | P31: Dettes fiscales et sociales | R31: 18 | T31: 1200000 | V31: 800000
A32: BJ | C32: Autres créances | E32: 8 | G32: 750000 | K32: =G32-I32 -> 750000 | M32: 500000 | N32: DM | P32: Autres dettes | R32: 19
A33: BK | C33: TOTAL ACTIF CIRCULANT | G33: =SUM(G27:G32) -> 5250000 | I33: =SUM(I27:I32) -> 0 | K33: =G33-I33 -> 5250000 | M33: =SUM(M27:M32) -> 4000000 | N33: DN | P33: Provisions pour risques à court terme | R33: 19
A34: BQ | C34: Titres de placement | E34: 9 | K34: =G34-I34 -> 0 | N34: DP | P34: TOTAL PASSIF CIRCULANT | T34: =SUM(T28:T33) -> 6200000 | V34: =SUM(V28:V33) -> 4800000
A35: BR | C35: Valeurs à encaisser | E35: 10 | K35: =G35-I35 -> 0 | N35: DQ | P35: Banques, crédits d'escompte | R35: 20 | T35: 500000 | V35: 350000
A36: BS | C36: Banques, chèques postaux, caisses et assimilés | E36: 11 | G36: 4500000 | K36: =G36-I36 -> 4500000 | M36: 3500000 | N36: DR | P36: Banques, établissements financiers et crédits de trésorerie | R36: 20
A37: BT | C37: TOTAL TRESORERIE-ACTIF | G37: =SUM(G34:G36) -> 4500000 | I37: =SUM(I34:I36) -> 0 | K37: =G37-I37 -> 4500000 | M37: =SUM(M34:M36) -> 3500000 | N37: DT | P37: TOTAL TRESORERIE-PASSIF | T37: =SUM(T35:T36) -> 500000 | V37: =SUM(V35:V36) -> 350000
A38: BU | C38: Ecart de conversion-Actif | E38: 12 | K38: =G38-I38 -> 0 | N38: DV | P38: Ecart de conversion-Passif | R38: 12
A39: BZ | C39: TOTAL GENERAL | G39: =G38+G37+G33+G26 -> 35680000 | I39: =I38+I37+I33+I26 -> 0 | K39: =G39-I39 -> 35680000 | M39: =M26+M33+M37+M38 -> 35830000 | N39: DZ | P39: TOTAL GENERAL | T39: =T27+T34+T37+T38 -> 46700000 | V39: =V27+V34+V37+V38 -> 44650000
C42: * A renseigner manuellement | P42: =K39-T39 -> -11020000
C43: *Trésorerie nette au 1er janvier N-1 (Trésorerie actif N-2 - Trésorerie passif N-2) | K43: 0
C44: *STOCKS ET ENCOURS N-2 | K44: 0
...

Sheet Cpte Résultat
C2: Désignation de l'entité: | D2: =+Bilan!D2 -> ELESYST SA | I2: Exercice clos le 31/12/ | J2: =+Bilan!Q2 -> 2019
C3: Numéro d'identification: | D3: =+Bilan!D3 -> MO1779U7P00197 | I3: Durée (en mois): | J3: =+Bilan!Q3 -> 12
C4: *Colonnes I (EXERCICE au 31/12/N) et I (EXERCICE au 31/12/N-1) à renseigner manuellement
A5: COMPTE DE RESULTAT AU 31 DECEMBRE N
A7: REF | C7: LIBELLES | G7: Note | I7: EXERCICE | K7: EXERCICE
I8: au 31/12/N | K8: au 31/12/N-1
I9: NET | K9: NET
A10: TA | C10: Ventes de marchandises | E10: A | F10: + | G10: 21 | I10: 55000000 | K10: 48000000
A11: RA | C11: Achats de marchandises | F11: - | G11: 22 | I11: 32000000 | K11: 26000000
A12: RB | C12: Variation de stocks de marchandises | F12: -/+ | G12: 6
A13: XA | C13: MARGE COMMERCIALE (Somme TA & RB) | I13: =I10-(I11+I12) -> 23000000 | K13: =K10-(K11+K12) -> 22000000
A14: TB | C14: Ventes des produits fabriqués | E14: B | F14: + | G14: 21
A15: TC | C15: Travaux, services vendus | E15: C | F15: + | G15: 21 | I15: 20000000 | K15: 16000000
A16: TD | C16: Produits accessoires | E16: D | F16: + | G16: 21 | I16: 3500000 | K16: 2800000
A17: XB | C17: CHIFFRE D'AFFAIRES (A + B + C + D) | I17: =I10+I14+I15+I16 -> 78500000 | K17: =K10+K14+K15+K16 -> 66800000
A18: TE | C18: Production stockée (ou déstockage) | F18: -/+ | G18: 6
A19: TF | C19: Produits immobilisées | G19: 21
A20: TG | C20: Subventions d'exploitation | G20: 21
A21: TH | C21: Autres produits | F21: + | G21: 21
A22: TI | C22: Transferts de charges d'exploitation | F22: + | G22: 12
A23: RC | C23: Achats de matières premières et fournitures liées | F23: - | G23: 22
A24: RD | C24: Variation de stocks de matières premières et fournitures liées | F24: -/+ | G24: 6
A25: RE | C25: Autres achats | F25: - | G25: 22 | I25: 3000000 | K25: 2500000
A26: RF | C26: Variation de stocks d'autres approvisionnements | F26: -/+ | G26: 6
A27: RG | C27: Transports | F27: - | G27: 23 | I27: 2850000 | K27: 2250000
A28: RH | C28: Services extérieurs | F28: - | G28: 24 | I28: 6000000 | K28: 5000000
A29: RI | C29: Impôts et taxes | F29: - | G29: 25 | I29: 2345000 | K29: 1950000
A30: RJ | C30: Autres charges | F30: - | G30: 26 | I30: 950000 | K30: 642000
A31: XC | C31: VALEUR AJOUTEE (XB + RA + RB) + (Somme TE à RJ) | I31: =(I17+I18+I19+I20+I21+I22)-(I11+I23+I24+I25+I26+I27+I28+I29+I30) -> 31355000 | K31: =(K17+K18+K19+K20+K21+K22)-(+K11+K23+K24+K25+K26+K27+K28+K29+K30) -> 28458000
A32: RK | C32: Charge de personnel | F32: - | G32: 27 | I32: 18255000 | K32: 17093000
A33: XD | C33: EXCEDENT BRUT D'EXPLOITATION (XC + RK) | G33: 28 | I33: =I31-I32 -> 13100000 | K33: =K31-K32 -> 11365000
A34: TJ | C34: Reprises d'amortissements, provisions et dépréciations | F34: + | G34: 28 | K34: 0
A35: RL | C35: Dotations aux amortissements, aux provisions et dépréciations | F35: - | G35: 3C & 28 | I35: 2500000 | K35: 2500000
A36: XE | C36: RESULTAT D'EXPLOITATION (XD + TJ + RL) | I36: =I33+I34-I35 -> 10600000 | K36: =K33+K34-K35 -> 8865000
A37: TK | C37: Revenus financiers et assimilés | F37: + | G37: 29
A38: TL | C38: Reprises de provisions et dépréciations financières | F38: + | G38: 28
A39: TM | C39: Transferts de charges financières | F39: + | G39: 12
A40: RM | C40: Frais financiers et charges assimilées | F40: - | G40: 29 | I40: 1200000 | K40: 965000
A41: RN | C41: Dotations aux provisions et aux dépréciations financières | F41: - | G41: 3C & 28
A42: XF | C42: RESULTAT FINANCIER (somme TK à RN) | I42: =(I37+I38+I39)-(I40+I41) -> -1200000 | K42: =(K37+K38+K39)-(K40+K41) -> -965000
...

Sheet Cash balance
B2: Désignation de l'entité: | C2: =+Bilan!D2 -> ELESYST SA | E2: Exercice clos le 31/12/ | F2: =+Bilan!Q2 -> 2019
B3: Numéro d'identification: | C3: =+Bilan!D3 -> MO1779U7P00197 | E3: Durée (en mois): | F3: =+Bilan!Q3 -> 12
B4: *Colonnes D (EXERCICE au 31/12/N) et F (EXERCICE au 31/12/N-1) à renseigner manuellement
B5: FLUX DE TRESORERIE DETAILLES
A7: REF | B7: LIBELLES | D7: EXERCICE N | F7: EXERCICE N-1
B9: Flux de trésorerie provenant des activités d'investissement (1) & (2)
A10: =+'Flux Trésorerie'!A20 -> FF | B10: - Décaissements liés aux acquisitions d'immobilisations incorporelles | D10: =-D11-D12-D13-D14 -> 0 | F10: =-F11-F12-F13-F14 -> 0
B11: Frais de développement et de prospection
B12: Brevets, licences, logiciels, et droits similaires
B13: Fonds commercial et droit au bail
B14: Autres immobilisations corporelles
A15: =+'Flux Trésorerie'!A21 -> FG | B15: - Décaissements liés aux acquisitions d'immobilisations corporelles | D15: =-D16-D17-D18-D19-D20-D21 -> 0 | F15: =-F16-F17-F18-F19-F20-F21 -> 0
B16: Terrains (dont le Placement en Net …………/………….)
B17: Bâtiments (dont le Placement en Net …………/………….)
B18: Aménagements, agencements et installations
B19: Matériel, mobilier, et actifs biologiques
B20: Matériel de transport
B21: Avances et acomptes versés sur immobilisations
A22: =+'Flux Trésorerie'!A22 -> FH | B22: - Décaissements liés aux acquisitions d'immobilisations financières | D22: =-D23-D24 -> 0 | F22: =-F23-F24 -> 0
B23: Titres de participation
B24: Autres immobilisations financières
A25: =+'Flux Trésorerie'!A23 -> FI | B25: + Encaissements liés aux cessions d'immobilisations incorporelles et corporelles | D25: =D26+D27+D28+D29+D30+D31+D32+D33+D34+D35 -> 0 | F25: =F26+F27+F28+F29+F30+F31+F32+F33+F34+F35 -> 0
B26: Frais de développement et de prospection
B27: Brevets, licences, logiciels, et droits similaires
B28: Fonds commercial et droit au bail
B29: Autres immobilisations corporelles
B30: Terrains (dont le Placement en Net …………/………….)
B31: Bâtiments (dont le Placement en Net …………/………….)
B32: Aménagements, agencements et installations
B33: Matériel, mobilier, et actifs biologiques
B34: Matériel de transport
B35: Avances et acomptes versés sur immobilisations
A36: =+'Flux Trésorerie'!A24 -> FJ | B36: + Encaissements liés aux cessions d'immobilisations financières | D36: =D37+D38 -> 0 | F36: =F37+F38 -> 0
B37: Titres de participation
B38: Autres immobilisations financières
A39: =+'Flux Trésorerie'!A25 -> ZC | B39: Flux de trésorerie provenant des activités d'investissement | D39: =D36+D25+D22+D15+D10 -> 0 | F39: =F36+F25+F22+F15+F10 -> 0
B41: Flux de trésorerie provenant du financement des capitaux propres
A42: =+'Flux Trésorerie'!A28 -> FK | B42: + Augmentation de capital par apports nouveaux
A43: =+'Flux Trésorerie'!A29 -> FL | B43: + Subventions d'investissement reçues
A44: =+'Flux Trésorerie'!A30 -> FM | B44: - Prélèvements sur le capital
...

Sheet Flux Trésorerie
C2: Désignation de l'entité: | D2: =+Bilan!D2 -> ELESYST SA | I2: Exercice clos le 31/12/ | J2: =+Bilan!Q2 -> 2019
C3: Numéro d'identification: | D3: =+Bilan!D3 -> MO1779U7P00197 | I3: Durée (en mois): | J3: =+Bilan!Q3 -> 12
A5: TABLEAU DE FLUX DE TRESORERIE
A7: REF | C7: LIBELLES | G7: Note | I7: EXERCICE N | K7: EXERCICE N-1
A8: ZA | C8: Trésorerie nette au 1er janvier (Trésorerie actif N-1 - Trésorerie passif N-1)* | E8: A | I8: =Bilan!M36-Bilan!V37 -> 3150000 | K8: =+K47 -> 0
C10: Flux de trésorerie provenant des activités opérationnelles
A11: FA | C11: Capacité d'Autofinancement Globale (CAFG) | I11: ='INDICATEURS FIN'!D35 -> 8500000 | K11: ='INDICATEURS FIN'!F35 -> 7500000
A12: FB | C12: - Actif circulant HAO | I12: =Bilan!K27 -> 0 | K12: =Bilan!M27 -> 0
A13: FC | C13: - Variations des stocks | I13: =Bilan!K28-Bilan!M28 -> 0 | K13: =+Bilan!M28-Bilan!K44 -> 0
A14: FD | C14: - Variations des créances | I14: =(Bilan!K31-Bilan!M31)+(Bilan!K32-Bilan!M32)+(Bilan!K30-Bilan!M30) -> 1250000 | K14: =+(Bilan!M30-Bilan!K45)+(Bilan!M31-Bilan!K46)+(Bilan!M32-Bilan!K47) -> 4000000
A15: FE | C15: + Variation du passif circulant | I15: =Bilan!T34-Bilan!V34 -> 1400000 | K15: =+Bilan!V34-Bilan!K48 -> 4800000
C16: Variation du BF lié aux activités opérationnelles (FB + FC + FD + FE) | I16: =SUM(I12:I15) -> 2650000 | K16: =SUM(K12:K15) -> 8800000
A17: ZB | C17: Flux de trésorerie provenant des activités opérationnelles (somme FA à FE) | E17: B | I17: =I11-(I12+I13+I14)+I15 -> 8650000 | K17: =K11-(K12+K13+K14)+K15 -> 8300000
C19: Flux de trésorerie provenant des activités d'investissement
A20: FF | C20: - Décaissements liés aux acquisitions d'immobilisations incorporelles | I20: ='Cash balance'!D10 -> 0 | K20: ='Cash balance'!F10 -> 0
A21: FG | C21: - Décaissements liés aux acquisitions d'immobilisations corporelles | I21: ='Cash balance'!D15 -> 0 | K21: ='Cash balance'!F15 -> 0
A22: FH | C22: - Décaissements liés aux acquisitions d'immobilisations financières | I22: ='Cash balance'!D22 -> 0 | K22: ='Cash balance'!F22 -> 0
A23: FI | C23: + Encaissements liés aux cessions d'immobilisations incorporelles et corporelles | I23: ='Cash balance'!D25 -> 0 | K23: ='Cash balance'!F25 -> 0
A24: FJ | C24: + Encaissements liés aux cessions d'immobilisations financières | I24: ='Cash balance'!D36 -> 0 | K24: ='Cash balance'!F36 -> 0
A25: ZC | C25: Flux de trésorerie provenant des activités d'investissement (somme FF à FJ) | E25: C | I25: =-(I20+I21+I22)+(I23+I24) -> 0 | K25: =-(K20+K21+K22)+(K23+K24) -> 0
C27: Flux de trésorerie provenant du financement des capitaux propres
A28: FK | C28: + Augmentation de capital par apports nouveaux | I28: ='Cash balance'!D42 -> 0 | K28: ='Cash balance'!F42 -> 0
A29: FL | C29: + Subventions d'investissement reçues | I29: ='Cash balance'!D43 -> 0 | K29: ='Cash balance'!F43 -> 0
A30: FM | C30: - Prélèvements sur le capital | I30: ='Cash balance'!D44 -> 0 | K30: ='Cash balance'!F44 -> 0
A31: FN | C31: - Dividendes versés | I31: ='Cash balance'!D45 -> 0 | K31: ='Cash balance'!F45 -> 0
A32: ZD | C32: Flux de trésorerie provenant des capitaux propres (somme FK à FN) | E32: D | I32: =(I28+I29)-(I30+I31) -> 0 | K32: =(K28+K29)-(K30+K31) -> 0
C34: Flux de trésorerie provenant du financement des capitaux étrangers
A35: FO | C35: + Emprunts | I35: ='Cash balance'!D49 -> 0 | K35: ='Cash balance'!F49 -> 0
A36: FP | C36: + Autres dettes financières | I36: ='Cash balance'!D50 -> 0 | K36: ='Cash balance'!F50 -> 0
A37: FQ | C37: - Remboursements des emprunts et autres dettes financières | I37: ='Cash balance'!D51 -> 0 | K37: ='Cash balance'!F51 -> 0
A38: ZE | C38: Flux de trésorerie provenant des capitaux étrangers (somme FO à FQ) | E38: E | I38: =SUM(I35:I37) -> 0 | K38: =SUM(K35:K37) -> 0
A39: ZF | C39: Flux de trésorerie provenant des activités de financement (D + E) | E39: F | I39: =I32+I38 -> 0 | K39: =K32+K38 -> 0
A41: ZG | C41: VARIATION DE LA TRESORERIE NETTE DE LA PERIODE (B + C + F) | E41: G | I41: =I17+I25+I39 -> 8650000 | K41: =K17+K25+K39 -> 8300000
A42: ZH | C42: Trésorerie nette au 31 décembre (G + A) (1) | E42: H | I42: =I41+I8 -> 11800000 | K42: =K41+K8 -> 8300000
A44: (1) Contrôle: Trésorerie actif N - Trésorerie passif N = | I44: =Bilan!K37-Bilan!T37 -> 4000000 | K44: =Bilan!M37-Bilan!V37 -> 3150000
I45: =I42-I44 -> 7800000 | K45: =K42-K44 -> 5150000

Sheet GRILLE NOTATION
A1: Désignation de l'entité: | B1: =+Bilan!D2 -> ELESYST SA | G1: Exercice clos le 31/12/ | H1: =+Bilan!Q2 -> 2019
A2: Numéro d'identification: | B2: =+Bilan!D3 -> MO1779U7P00197 | G2: Durée (en mois): | H2: =+Bilan!Q3 -> 12
A4: CRITERES PRINCIPAUX | B4: PONDERATION | C4: N° SOUS-CRITERES | D4: Taux Pondération | F4: SOUS-CRITERES | G4: VALEUR PAR SOUS-CRITERE | H4: NOTE PAR SOUS-CRITERE | I4: NOTE PONDEREE | J4: NOTE PONDEREE CRITERE
A5: ACTIVITE | B5: 0.1 | C5: 1 | D5: 0.015 | E5: positionnement concurentiel sur le marché | G5: Plutôt Moyen | H5: =IF(G5="","",VLOOKUP(G5,'tableaux annexes'!C:D,2,0)) -> 6 | I5: =+D5*H5 -> 0.09 | J5: ACTIVITE
C6: 2 | D6: 0.01 | E6: Tendance structurelle du marché | G6: très bonne A | H6: =IF(G6="","",VLOOKUP(G6,'tableaux annexes'!K:M,2,0)) -> 1 | I6: =+D6*H6 -> 0.01
C7: 3 | D7: 0.01 | E7: Marchés cycliques ou à prix volatils | G7: peu | H7: =IF(G7="","",VLOOKUP(G7,'tableaux annexes'!G:H,2,0)) -> 3 | I7: =+D7*H7 -> 0.03
C8: 4 | D8: 0.02 | E8: Portefeuille produit | G8: plutot bien positionné | H8: =IF(G8="","",VLOOKUP(G8,'tableaux annexes'!O:P,2,0)) -> 3 | I8: =+D8*H8 -> 0.06
C9: 5 | D9: 0.02 | E9: Pression liée à la clientèle | G9: très modérée | H9: =IF(G9="","",VLOOKUP(G9,'tableaux annexes'!S:T,2,0)) -> 1 | I9: =+D9*H9 -> 0.02
C10: 6 | D10: 0.015 | E10: Barrière à l'entrée | G10: plutôt faibles | H10: =IF(G10="","",VLOOKUP(G10,'tableaux annexes'!W:X,2,0)) -> 5 | I10: =+D10*H10 -> 0.075
C11: 7 | D11: 0.01 | E11: Visibilité du secteur | G11: très bonne B | H11: =IF(G11="","",VLOOKUP(G11,'tableaux annexes'!AA:AB,2,0)) -> 2 | I11: =+D11*H11 -> 0.02 | J11: =SUM(I5:I11) -> 0.305
A13: GESTION ET STRATEGIE | B13: 0.2 | C13: 8 | D13: 0.04 | E13: Qualité du profil du drigeant | G13: très mauvaise A | H13: =IF(G13="","",VLOOKUP(G13,'tableaux annexes'!AE:AF,2,0)) -> 9 | I13: =+D13*H13 -> 0.36 | J13: GESTION & STRATEGIE
C14: 9 | D14: 0.01 | E14: Qualité de l'organisation | G14: bonne | H14: =IF(G14="","",VLOOKUP(G14,'tableaux annexes'!AM:AN,2,0)) -> 3 | I14: =+D14*H14 -> 0.03
C15: 10 | D15: 0.01 | E15: Qualité du système de contrôle interne | G15: excellente | H15: =IF(G15="","",VLOOKUP(G15,'tableaux annexes'!AM:AN,2,0)) -> 1 | I15: =+D15*H15 -> 0.01
C16: 11 | D16: 0.01 | E16: Qualité de la Stratégie commerciale et marketing | G16: très bonne | H16: =IF(G16="","",VLOOKUP(G16,'tableaux annexes'!AM:AN,2,0)) -> 2 | I16: =+D16*H16 -> 0.02
C17: 12 | D17: 0.02 | E17: Qualité des Moyens humains et techniques | G17: assez bonne | H17: =IF(G17="","",VLOOKUP(G17,'tableaux annexes'!AM:AN,2,0)) -> 4 | I17: =+D17*H17 -> 0.08
C18: 13 | D18: 0.03 | E18: Adéquation des investissements / Impact sur l'emploi | G18: insuffisants A | H18: =IF(G18="","",VLOOKUP(G18,'tableaux annexes'!AQ:AR,2,0)) -> 7 | I18: =+D18*H18 -> 0.21
C19: 14 | D19: 0.03 | E19: Maîtrise des coûts de productivité / Impact sur la création des richesses | G19: limité | H19: =IF(G19="","",VLOOKUP(G19,'tableaux annexes'!AU:AV,2,0)) -> 8 | I19: =+D19*H19 -> 0.24
C20: 15 | D20: 0.03 | E20: Cohérence des options stratégiques / Impact sur l'environnement | G20: très fiables dans l'ensemble | H20: =IF(G20="","",VLOOKUP(G20,'tableaux annexes'!AY:AZ,2,0)) -> 1 | I20: =+D20*H20 -> 0.03
C21: 16 | D21: 0.01 | E21: Qualité des relations sociales | G21: très bonne | H21: =IF(G21="","",VLOOKUP(G21,'tableaux annexes'!BC:BD,2,0)) -> 2 | I21: =+D21*H21 -> 0.02
C22: 17 | D22: 0.01 | E22: Succession des Dirigeants | G22: Garantie par le cadre juridique et fonctionnel | H22: =IF(G22="","",VLOOKUP(G22,'tableaux annexes'!BG:BH,2,0)) -> 3 | I22: =+D22*H22 -> 0.03 | J22: =SUM(I13:I22) -> 1.03
A24: FINANCES | B24: PONDERATION | E24: SOUS-CRITERES | G24: VALEURS SOUS-CRITERES | H24: NOTE PAR SOUS-CRITERES | I24: NOTE PONDEREE | J24: NOTE PONDEREE CRITERE
A25: STRUCTURE FINANCIERE | B25: 0.45 | C25: 18 | D25: 0.03 | F25: Dynamique de l'Equilibre Financier (FR/BFR) | G25: ='INDICATEURS FIN'!D78 -> -14.810526 | H25: =IF(G25<0.2,10,IF(G25<=0.5,9,IF(G25<=0.8,8,IF(G25<=1,7,IF(G25<=1.2,6,IF(G25<=1.4,5,IF(G25<=1.6,4,IF(G25<=1.8,3,IF(G25<=2,2,1))))))))) -> 10 | I25: =H25*D25 -> 0.3 | J25: FINANCIER
C26: 19 | D26: 0.03 | F26: Ratio d'endettement global ((Actifs - Capitaux propres)/ Actifs) <1 | G26: ='INDICATEURS FIN'!D79 -> 0.10313901 | H26: =IF(G26<0.1,1,IF(G26<=0.2,2,IF(G26<0.4,3,IF(G26<0.45,4,IF(G26<0.49,5,IF(G26<0.6,6,IF(G26<0.7,7,IF(G26<0.8,8,IF(G26<1,9,10))))))))) -> 2 | I26: =H26*D26 -> 0.06
A27: LIQUIDITE ET SOLVABILITE | C27: 20 | D27: 0.04 | F27: Capacité de Remboursement (DLMT/CAFG) | G27: ='INDICATEURS FIN'!D80 -> 0.94117647 | H27: =IF(G27<1,1,IF(G27<1.5,2,IF(G27<2,3,IF(G27<3,4,IF(G27<3.4,5,IF(G27<3.8,6,IF(G27<4,7,IF(G27<4.4,8,IF(G27<5,9,10))))))))) -> 1 | I27: =H27*D27 -> 0.04
C28: 21 | D28: 0.04 | F28: Couverture des frais financiers (FTAO/FF) | G28: ='INDICATEURS FIN'!D81 -> 7.2083333 | H28: =IF(G28>6,1,IF(G28>5,2,IF(G28>4,3,IF(G28>3,4,IF(G28=3,5,IF(G28<3,6,IF(G28<2,7,IF(G28<1.5,8,IF(G28<1,9,10))))))))) -> 1 | I28: =H28*D28 -> 0.04
C29: 22 | D29: 0.04 | F29: Solvabilité globale Risque liquidatif (Ressources Propres /Total Bilan) | G29: ='INDICATEURS FIN'!D82 -> 0.68522484 | H29: =IF(G29<3%,10,IF(G29<5,9,IF(G29<10%,8,IF(G29<15%,7,IF(G29<20%,6,IF(G29<25%,5,IF(G29=25%,4,IF(G29>25%,3,IF(G29>30%,2,IF(G29>35%,1)))))))))) -> 9 | I29: =H29*D29 -> 0.36
C30: 23 | D30: 0.04 | F30: Liquidité générale (Ratio de FR= Actifs circulants/ Passifs circulants)>1 | G30: ='INDICATEURS FIN'!D83 -> 0.84677419 | H30: =IF(G30<0.2,10,IF(G30<=0.5,9,IF(G30<=0.8,8,IF(G30<=1,7,IF(G30<=1.2,6,IF(G30<=1.4,5,IF(G30<=1.6,4,IF(G30<=1.8,3,IF(G30<=2,2,1))))))))) -> 7 | I30: =H30*D30 -> 0.28
A31: PERFORMANCE DE L'ACTIVITE ET RENTABILITE | C31: 24 | D31: 0.05 | F31: Rentabilité d'exploitation par rapport au CA (EBE/ CA)>30% | G31: ='INDICATEURS FIN'!D84 -> 5.9923664 | H31: =IF(G31<10%,10,IF(G31<15%,9,IF(G31<25%,8,IF(G31<30%,7,IF(G31=30%,6,IF(G31>30%,5,IF(G31>35%,4,IF(G31>40%,3,IF(G31>45%,2,IF(G31>50%,1)))))))))) -> 5 | I31: =H31*D31 -> 0.25
C32: 25 | D32: 0.04 | F32: Rentabilité économique ( REX/ACTIF)>10% | G32: ='INDICATEURS FIN'!D85 -> 0.2970852 | H32: =IF(G32<1%,10,IF(G32<3%,9,IF(G32<5%,8,IF(G32<7.5%,7,IF(G32<10%,6,IF(G32=10%,5,IF(G32>12.5%,4,IF(G32>15%,3,IF(G32>17.5%,2,IF(G32>20%,1)))))))))) -> 4 | I32: =H32*D32 -> 0.16
C33: 26 | D33: 0.04 | F33: Rentabilité Financière (RN/Capitaux propres)>10% | G33: ='INDICATEURS FIN'!D86 -> 5.3333333 | H33: =IF(G33<1%,10,IF(G33<3%,9,IF(G33<5%,8,IF(G33<7.5%,7,IF(G33<10%,6,IF(G33=10%,5,IF(G33>12.5%,4,IF(G33>15%,3,IF(G33>17.5%,2,IF(G33>20%,1)))))))))) -> 4 | I33: =H33*D33 -> 0.16
C34: 27 | D34: 0.04 | F34: Capacité d'endettement (Ressources Propres/Dettes structurelles)>1 | G34: ='INDICATEURS FIN'!D87 -> 4 | H34: =IF(G34<0.2,10,IF(G34<0.5,9,IF(G34<0.8,8,IF(G34<1,7,IF(G34=1,6,IF(G34>1.2,5,IF(G34>1.4,4,IF(G34>1.6,3,IF(G34>1.8,2,IF(G34>2,1)))))))))) -> 5 | I34: =H34*D34 -> 0.2
A35: OUTILS D'AJUSTEMENT | C35: 28 | D35: 0.02 | F35: Délai Client ( (créances client /CA)*365) | G35: ='INDICATEURS FIN'!D88 -> 13.949045 | H35: =IF(G35<10,1,IF(G35<20,2,IF(G35<30,3,IF(G35<40,4,IF(G35<50,5,IF(G35<60,6,IF(G35<70,7,IF(G35<80,8,IF(G35<90,9,10))))))))) -> 2 | I35: =H35*D35 -> 0.04
C36: 29 | D36: 0.02 | F36: Délai Fournisseur ( (dettes fournisseurs /Achats à crédit)*365) | G36: ='INDICATEURS FIN'!D89 -> 243.33333 | H36: =IF(G36<10,10,IF(G36<=20,9,IF(G36<=30,8,IF(G36<=40,7,IF(G36<=50,6,IF(G36<=60,5,IF(G36<=70,4,IF(G36<=80,3,IF(G36<=90,2,1))))))))) -> 1 | I36: =H36*D36 -> 0.02
C37: 30 | D37: 0.02 | F37: Délai d'Ecoulement des stocks ( (stock moyen/Coûts des produits vendus)*365 ) | G37: ='INDICATEURS FIN'!D90 -> 0 | H37: =IF(G37<20,1,IF(G37<40,2,IF(G37<60,3,IF(G37<80,4,IF(G37<100,5,IF(G37<120,6,IF(G37<140,7,IF(G37<160,8,IF(G37<180,9,10))))))))) -> 1 | I37: =H37*D37 -> 0.02 | J37: =SUM(I25:I37) -> 1.93
A39: QUALITE DE L'INFORMATION FINANCIERE ET GARANTIES | B39: 0.25 | C39: 31 | D39: 0.05 | E39: Fiabilité des prévisions / Evolution des produits & charges | G39: fiable | H39: =IF(G39="","",VLOOKUP(G39,'tableaux annexes'!BK:BL,2,0)) -> 2 | I39: =+D39*H39 -> 0.1 | J39: QUALITE INFORMATIONS
C40: 32 | D40: 0.05 | E40: Représentation fidèle réalité comptable et financière/ Transparence des transactions | G40: excellente | H40: =IF(G40="","",VLOOKUP(G40,'tableaux annexes'!BO:BP,2,0)) -> 1 | I40: =+D40*H40 -> 0.05
C41: 33 | D41: 0.05 | E41: Implication du dirigeant / Surface financière des promoteurs | G41: très facile en permanence | H41: =IF(G41="","",VLOOKUP(G41,'tableaux annexes'!BS:BT,2,0)) -> 1 | I41: =+D41*H41 -> 0.05
C42: 34 | D42: 0.1 | E42: Qualité des garanties & Actifs cessibles | G42: oui, rapidement et importants | H42: =IF(G42="","",VLOOKUP(G42,'tableaux annexes'!BW:BX,2,0)) -> 1 | I42: =+D42*H42 -> 0.1 | J42: =SUM(I39:I42) -> 0.3
G43: NOTE PONDEREE FINALE / CRITERE | I43: NOTATION PME
G44: =+J42+J37+J22+J11 -> 3.565 | I44: =IF(G44<1.5,"SME1",IF(G44<2.75,"SME2",IF(G44<3.5,"SME3",IF(G44<3.75,"SME4",IF(G44<4,"SME4",IF(G44<5,"SME5",IF(G44<6,"SME6",IF(G44<7,"SME7",IF(G44<8,"SME7-",IF(G44<9,"SME8",IF(G44<9.7,"SME8-"))))))))))) -> SME4

Sheet INDICATEURS FIN
A2: Désignation de l'entité: | B2: =+Bilan!D2 -> ELESYST SA | F2: Exercice clos le 31/12/ | G2: =+Bilan!Q2 -> 2019
A3: Numéro d'identification: | B3: =+Bilan!D3 -> MO1779U7P00197 | F3: Durée (en mois): | G3: =+Bilan!Q3 -> 12
A6: FICHE DE SYNTHESE DES PRINCIPAUX INDICATEURS FINANCIERS
A8: EN MILLIONS DE FRANCS | D8: Année N | F8: Année N-1 | H8: Variation en %
A10: ANALYSE DE L'ACTIVITE
A11: SOLDES INTERMEDIAIRES DE GESTION | H11: =(D11-F11)/F11 -> #DIV/0!
A12: CHIFFRE D'AFFAIRES | D12: ='Cpte Résultat'!I17 -> 78500000 | F12: ='Cpte Résultat'!K17 -> 66800000 | H12: =(D12-F12)/F12 -> 0.1751497
A13: MARGE COMMERCIALE | D13: ='Cpte Résultat'!I13 -> 23000000 | F13: ='Cpte Résultat'!K13 -> 22000000 | H13: =(D13-F13)/F13 -> 0.045454545
A14: VALEUR AJOUTEE | D14: ='Cpte Résultat'!I31 -> 31355000 | F14: ='Cpte Résultat'!K31 -> 28458000 | H14: =(D14-F14)/F14 -> 0.10179914
A15: EXCEDENT BRUT D'EXPLOITATION (EBE) | D15: ='Cpte Résultat'!I33 -> 13100000 | F15: ='Cpte Résultat'!K33 -> 11365000 | H15: =(D15-F15)/F15 -> 0.15266168
A16: RESULTAT D'EXPLOITATION | D16: ='Cpte Résultat'!I36 -> 10600000 | F16: ='Cpte Résultat'!K36 -> 8865000 | H16: =(D16-F16)/F16 -> 0.19571348
A17: RESULTAT FINANCIER | D17: ='Cpte Résultat'!I42 -> -1200000 | F17: ='Cpte Résultat'!K42 -> -965000 | H17: =(D17-F17)/F17 -> 0.24352332
A18: RESULTAT DES ACTIVITES ORDINAIRES | D18: ='Cpte Résultat'!I43 -> 9400000 | F18: ='Cpte Résultat'!K43 -> 7900000 | H18: =(D18-F18)/F18 -> 0.18987342
A19: RESULTAT HORS ACTIVITES ORDINAIRES | D19: ='Cpte Résultat'!I48 -> 0 | F19: ='Cpte Résultat'!K48 -> 0 | H19: =(D19-F19)/F19 -> #DIV/0!
A20: RESULTAT NET | D20: ='Cpte Résultat'!I51 -> 6000000 | F20: ='Cpte Résultat'!K51 -> 5000000 | H20: =(D20-F20)/F20 -> 0.2
A21: DETERMINATION DE LA CAPACITE D'AUTOFINANCEMENT | H21: =(D21-F21)/F21 -> #DIV/0!
A22: EBE | D22: =D15 -> 13100000 | F22: =F15 -> 11365000 | H22: =(D22-F22)/F22 -> 0.15266168
A23: + Valeurs comptables des cessions courantes d’immobilisation (compte 654) | D23: ='Cpte Résultat'!I46 -> 0 | F23: ='Cpte Résultat'!K46 -> 0 | H23: =(D23-F23)/F23 -> #DIV/0!
A24: - Produits des cessions courantes d’immobilisation (compte 754) | D24: ='Cpte Résultat'!I44 -> 0 | F24: ='Cpte Résultat'!K44 -> 0 | H24: =(D24-F24)/F24 -> #DIV/0!
A25: = CAPACITE D'AUTOFINANCEMENT D'EXPLOITATION | D25: =D22+D23-D24 -> 13100000 | F25: =F22+F23-F24 -> 11365000 | H25: =(D25-F25)/F25 -> 0.15266168
A26: + Revenus financiers | D26: ='Cpte Résultat'!I37 -> 0 | F26: ='Cpte Résultat'!K37 -> 0 | H26: =(D26-F26)/F26 -> #DIV/0!
A27: + Gains de change | H27: =(D27-F27)/F27 -> #DIV/0!
A28: + Transferts de charges financières | D28: ='Cpte Résultat'!I39 -> 0 | F28: ='Cpte Résultat'!K39 -> 0 | H28: =(D28-F28)/F28 -> #DIV/0!
A29: + Produits HAO | D29: ='Cpte Résultat'!I45 -> 0 | F29: ='Cpte Résultat'!K45 -> 0 | H29: =(D29-F29)/F29 -> #DIV/0!
A30: + Transferts de charges HAO | H30: =(D30-F30)/F30 -> #DIV/0!
A31: - Frais financiers | D31: ='Cpte Résultat'!I40 -> 1200000 | F31: ='Cpte Résultat'!K40 -> 965000 | H31: =(D31-F31)/F31 -> 0.24352332
A32: - Pertes de change | H32: =(D32-F32)/F32 -> #DIV/0!
A33: - Participation | D33: ='Cpte Résultat'!I49 -> 0 | F33: ='Cpte Résultat'!K49 -> 0 | H33: =(D33-F33)/F33 -> #DIV/0!
A34: - Impôts sur les résultats | D34: ='Cpte Résultat'!I50 -> 3400000 | F34: ='Cpte Résultat'!K50 -> 2900000 | H34: =(D34-F34)/F34 -> 0.17241379
A35: = CAPACITE D'AUTOFINANCEMENT GLOBALE (C.A.F.G.) | D35: =D25+(D26+D27+D28+D29+D30)-(D31+D32+D33+D34) -> 8500000 | F35: =F25+(F26+F27+F28+F29+F30)-(F31+F32+F33+F34) -> 7500000 | H35: =(D35-F35)/F35 -> 0.13333333
A36: - Distributions de dividendes opérées durant l'exercice | D36: =Bilan!K49 -> 0 | F36: =Bilan!M49 -> 0 | H36: =(D36-F36)/F36 -> #DIV/0!
A37: = AUTOFINANCEMENT | D37: =D35-D36 -> 8500000 | F37: =F35-F36 -> 7500000 | H37: =(D37-F37)/F37 -> 0.13333333
A39: ANALYSE DE LA RENTABILITE
A40: Rentabilité économique = Résultat d’exploitation (a) /Capitaux propres + dettes financières | D40: =D16/(Bilan!T12+Bilan!T23) -> 0.46086957 | F40: =F16/(Bilan!V12+Bilan!V23) -> 0.3546 | H40: =(D40-F40)/F40 -> 0.29968857
A41: Rentabilité financière = Résultat net/Capitaux propres | D41: =D20/Bilan!T12 -> 0.4 | F41: =F20/Bilan!V12 -> 0.33333333 | H41: =(D41-F41)/F41 -> 0.2
A43: ANALYSE DE LA STRUCTURE FINANCIERE
A44: Capitaux propres et ressources assimilées | D44: =Bilan!T22 -> 32000000 | F44: =Bilan!V22 -> 29500000 | H44: =(D44-F44)/F44 -> 0.084745763
A45: + Dettes financières* et autres ressources assimilées (b) | D45: =Bilan!T26 -> 8000000 | F45: =Bilan!V26 -> 10000000 | H45: =(D45-F45)/F45 -> -0.2
A46: = ressources stables | D46: =D44+D45 -> 40000000 | F46: =F44+F45 -> 39500000 | H46: =(D46-F46)/F46 -> 0.012658228
A47: - Actif immobilisé (b) | D47: =Bilan!K26 -> 25930000 | F47: =Bilan!M26 -> 28330000 | H47: =(D47-F47)/F47 -> -0.084715849
...

Sheet GRILLE SOUCHE
A1: Désignation de l'entité: | B1: =+Bilan!D2 -> ELESYST SA | G1: Exercice clos le 31/12/ | H1: =+Bilan!Q2 -> 2019
A2: Numéro d'identification: | B2: =+Bilan!D3 -> MO1779U7P00197 | G2: Durée (en mois): | H2: =+Bilan!Q3 -> 12
A4: CRITERES PRINCIPAUX | B4: PONDERATION | C4: N° SOUS-CRITERES | G4: 1 | H4: 2 | I4: 3 | J4: 4 | K4: 5 | L4: 6 | M4: 7 | N4: 8 | O4: 9 | P4: 10
A5: ACTIVITE | B5: 0.1 | C5: 1 | D5: Positionnement concurentiel sur le marché* | G5: Très significatif | H5: Significatif | I5: Bon | J5: Plutôt Bon | K5: Moyen | L5: Plutôt Moyen | M5: Faible | N5: Limité | O5: Mauvais | P5: Très Mauvais
C6: 2 | D6: Tendance structurelle du marché | G6: Très bonne | H6: Très bonne | I6: Bonne | J6: Moyenne | K6: Faible | L6: Plutôt | M6: Plutôt | N6: En baisse | O6: En forte | P6: Secteur en difficulté
L7: en stagnation | M7: en baisse | N7: sensible | O7: baisse | P7: ou en déclin
C8: 3 | D8: Marchés cycliques ou à prix volatils | G8: Non | H8: Non ou très peu | I8: Peu | J8: Légèrement | K8: Modérément | L8: Modérément | M8: Fortement | N8: Fortement | O8: Très fortement | P8: Très fortement
C9: 4 | D9: Portefeuille produit | G9: Exremement bien | H9: Très bien | I9: Plutôt bien | J9: Assez bien | K9: Moyennement | L9: Moyennement | M9: Plutôt mal positionné | N9: Mal positionné | O9: Renouvellement | P9: Obsolescence
G10: positionné | H10: positionné | I10: positionné | J10: positionné | K10: positionné | L10: positionné | M10: et/ou étroit | N10: et/ou très étroit | O10: non assuré | P10: marquée
C11: 5 | D11: Pression liée à la clientèle | G11: Très | H11: Modérée | I11: Plutôt | J11: Plutôt | K11: Assez | L11: Sensible | M11: Assez | N11: Forte | O11: Très | P11: Extrêmement
G12: modérée | I12: Faible | J12: sensible | K12: sensible | M12: forte | O12: forte | P12: Forte
C13: 6 | D13: Barrière à l'entrée | G13: Très élevées | H13: Très élevées | I13: Elevées | J13: Assez élevées | K13: Plutôt faibles | L13: Faibles | M13: Très faibles | N13: Très faibles | O13: Inexistantes | P13: Inexistantes
C14: 7 | D14: Visibilité du secteur | G14: Très bonne | H14: Très bonne | I14: Bonne | J14: Bonne | K14: Moyenne | L14: Limitée | M14: Plutôt faible | N14: Faible | O14: Très faible | P14: Extrêmement faible
A16: GESTION ET STRATEGIE | B16: 0.2 | C16: 8 | D16: Qualite du profil du dirigeant | G16: Excellente | H16: Très bonne | I16: Bonne | J16: Assez bonne | K16: Moyennes | L16: Plutôt moyenne | M16: mauvaise | N16: Limitées | O16: Très mauvaise | P16: très mauvaise
C17: 9 | D17: Qualité de l'organisation | G17: Excellente | H17: Très bonne | I17: Bonne | J17: Assez bonne | K17: Moyennes | L17: Plutôt moyenne | M17: mauvaise | N17: Limitées | O17: Très mauvaise | P17: très mauvaise
C18: 10 | D18: Qualité du système de contrôle interne | G18: Excellente | H18: Très bonne | I18: Bonne | J18: Assez bonne | K18: Moyennes | L18: Plutôt moyenne | M18: mauvaise | N18: Limitées | O18: Très mauvaise | P18: très mauvaise
C19: 11 | D19: Qualité de la Stratégie commerciale et marketing | G19: Excellente | H19: Très bonne | I19: Bonne | J19: Assez bonne | K19: Moyennes | L19: Plutôt moyenne | M19: mauvaise | N19: Limitées | O19: Très mauvaise | P19: très mauvaise
C20: 12 | D20: Qualité desMoyens humains et techniques | G20: Excellente | H20: Très bonne | I20: Bonne | J20: Assez bonne | K20: Moyennes | L20: Plutôt moyenne | M20: mauvaise | N20: Limitées | O20: Très mauvaise | P20: très mauvaise
C21: 13 | D21: Adéquation des investissements / Impact sur l'emploi | G21: Important | H21: Importants | I21: Assez | J21: Suffisants | K21: Suffisants | L21: Plutôt faibles | M21: Faibles | N21: Insuffisants | O21: Très insuffisants | P21: Très insuffisants
G22: bien adaptés | H22: adaptés | I22: importants
C23: 14 | D23: Maîtrise des coûts de productivité / Impact la création de richesses | G23: Excellente | H23: Très bonne | I23: Bonne | J23: Assez bonne | K23: Moyennes | L23: Plutôt faible | M23: Faibles | N23: Limitées | O23: Très limitée | P23: Inexistantes
C24: 15 | D24: Cohérence des options stratégiques / Impact sur l'environnement | G24: Très cohérents | H24: Cohérents | I24: Plutôt | J24: Plutôt | K24: Moyennement | L24: Pas toujours | M24: Peu cohérents | N24: Peu ou pas cohérents | O24: Pas cohérents | P24: Pas cohérents
G25: dans l'ensemble | I25: cohérents | J25: cohérents | K25: cohérents | L25: cohérents | N25: ou non communiquées
C26: 16 | D26: Qualité des relations sociales | G26: Excellente | H26: Très bonne | I26: Bonne | J26: Assez bonne | K26: Moyennes | L26: Plutôt faible | M26: Faibles | N26: Limitées | O26: Très limitée | P26: Inexistantes
C27: 17 | D27: Succession des Dirigeants | M27: Se pose à M.T. | N27: Se pose à C.T. | O27: Problème aigu | P27: Problème aigu
M28: relève non prévue | N28: relève non assurée | O28: de succession | P28: de succession
A31: FINANCES | B31: PONDERATION | C31: N° SOUS-CRITERES | D31: SOUS-CRITERES | F31: REFERENCE | G31: 1 | H31: 2 | I31: 3 | J31: 4 | K31: 5 | L31: 6 | M31: 7 | N31: 8 | O31: 9 | P31: 10
A32: STRUCTURE FINANCIERE | B32: 0.45 | C32: 18 | E32: Dynamique de l'Equilibre Financier (FR/BFR) | F32: > 1 | G32: (> 2) | H32: ]2 ; 1,8] | I32: ]1,8 ; 1,6 ] | J32: ]1,6 ; 1,4 ] | K32: ]1,4 ; 1,2 ] | L32: ]1,2 ; 1] | M32: ]1 ; 0,8 ] | N32: ]0,8 ; 0,5 ] | O32: ]0,5 ; 0,2 ] | P32: (< 0,2)
C33: 19 | E33: Ratio d'endettement global ((Actifs - Capitaux propres)/ Actifs) <1 | F33: < 1 | G33: (< 0,1) | H33: ]0,1;0,2[ | I33: 0.3 | J33: ]0,4 ; 0,45 ] | K33: ]0,45 ; 0,49 ] | L33: 0.5 | M33: 0.6 | N33: 0.7 | O33: ]0,8 ; 1 ] | P33: (> 1)
A34: LIQUIDITE ET SOLVABILITE | C34: 20 | E34: Capacité de Remboursement (DLMT/CAFG) | F34: < 3 | G34: (< 1) | H34: ]1; 1,5 ] | I34: ]1,5 ; 2] | J34: ]2 ; 3 ] | K34: ]3 ; 3,4 ] | L34: ]3,4 ; 3,8 ] | M34: ]3,8 ; 4 ] | N34: ]4 ; 4,4 ] | O34: ]4,4 ; 5 ] | P34: (> 5)
C35: 21 | E35: Couverture des frais financiers (FTAO/FF) | F35: >3 | G35: >6 | H35: >5 | I35: >4 | J35: >3 | K35: =3 -> 3 | L35: <3 | M35: <2 | N35: <1,5 | O35: <1 | P35: <0,5
C36: 22 | E36: Solvabilité globale Risque liquidatif ( Ressources Propres/Total Bilan) | F36: >25% | G36: >35% | H36: >30% | I36: >25% | J36: =25% | K36: <25% | L36: <20% | M36: <15% | N36: <10% | O36: <5% | P36: <3%
C37: 23 | E37: Liquidité générale (Ratio de FR= Actifs circulants/ Passifs circulants)>1 | F37: > 1 | G37: ( > 2) | H37: ]2 ; 1,8 ] | I37: ]1,8 ; 1,6 ] | J37: ]1,6 ; 1,4 ] | K37: ]1,4 ; 1,2 ] | L37: ]1,2 ; 1 ] | M37: ]1 ; 0,8 ] | N37: ]0,8 ; 0,5 ] | O37: ]0,5 ; 0,2 ] | P37: (< 0,2)
A38: PERFORMANCE DE L'ACTIVITE ET RENTABILITE | C38: 24 | E38: Rentabilité d'exploitation par rapport au CA (EBE/ CA) | F38: > 30% | G38: >50% | H38: >45% | I38: >40% | J38: >35% | K38: >30% | L38: =30% | M38: <30% | N38: <25% | O38: <15% | P38: <10%
C39: 25 | E39: Rentabilité économique ( REX/ACTIF) | F39: > 10% | G39: >20% | H39: >17,5% | I39: >15% | J39: >12,5% | K39: =10% | L39: <10% | M39: <7,5% | N39: <5% | O39: <3% | P39: <1%
C40: 26 | E40: Rentabilité Financière (RN/Capitaux propres) | F40: > 10% | G40: >20% | H40: >17,5% | I40: >15% | J40: >12,5% | K40: =10% | L40: <10% | M40: <7,5% | N40: <5% | O40: <3% | P40: <1%
C41: 27 | E41: Capacité d'endettement (Ressources Propres/Dettes structurelles)>1 | F41: >1 | G41: ( > 2) | H41: ]2 ; 1,8 ] | I41: ]1,8 ; 1,6 ] | J41: ]1,6 ; 1,4 ] | K41: ]1,4 ; 1,2 ] | L41: ]1,2 ; 1 ] | M41: ]1 ; 0,8 ] | N41: ]0,8 ; 0,5 ] | O41: ]0,5 ; 0,2 ] | P41: (< 0,2)
A42: OUTILS D'AJUSTEMENT | C42: 28 | E42: Délai Client ( (créances client /CA)*365) | F42: < 90 Jours | G42: (< 10) | H42: [10 ; 20 ] | I42: ]20 ; 30 ] | J42: ]30 ; 40] | K42: ]40 ; 50 ] | L42: ]50 ; 60 ] | M42: ]60 ; 700 ] | N42: ]70 ; 80 ] | O42: ]80 ; 90 ] | P42: ( >90 )
C43: 29 | E43: Délai Fournisseur ( (dettes fournisseurs /Achats à crédit)*365) | F43: > 90 jours | G43: ( >90 ) | H43: [90 ; 80 ] | I43: ]80 ; 70 ] | J43: ]70 ; 60 ] | K43: ]60 ; 50 ] | L43: ]50 ; 40 ] | M43: ]40 ; 30 ] | N43: ]30 ; 20 ] | O43: ]20 ; 10 ] | P43: (< 10)
C44: 30 | E44: Délai d'Ecoulement des stocks ( (stock moyen/Coûts des produits vendus)*365 ) | F44: < 90 jours | G44: (< 20) | H44: [20 ; 40 ] | I44: ]40 ; 60 ] | J44: ]60 ; 80 ] | K44: ]80 ; 100 ] | L44: ]100 ; 120 ] | M44: ]120 ; 140 ] | N44: ]140 ; 160 ] | O44: ]160 ; 180 ] | P44: (>180 )
...

Sheet MARCHE
A1: Taille du marché et Positionnement de l'entreprise sur le marché
A2: TYPE DE MARCHE (1) position sur le marché | B2: Mondial ou géographiquement très diversifié (2) | C2: REGIONALE OU Zone géographique diversifiée (3) | D2: Local / PAYS
A3: Significatif | B3: 1 à 2 | C3: 3 à 4 | D3: 4 à 5
A4: Faible (5) | B4: 3 à 4 | C4: 4 à 7 | D4: 8 à 10
A8: Note des valeurs du sous-critère PSLM | B8: Valeur Sous-critère | C8: Commentaires
A9: 1 | B9: ='GRILLE SOUCHE'!G5 -> Très significatif | C9: Marché mondial ou géographiquement très diversifié et parts de marché significatives
A10: 2 | B10: ='GRILLE SOUCHE'!H5 -> Significatif | C10: Marché mondial ou géographiquement diversifié et parts de marché importantes
A11: 3 | B11: ='GRILLE SOUCHE'!I5 -> Bon | C11: Marché régional ou zone géographique diversifiée et parts de marché significatives
A12: 4 | B12: ='GRILLE SOUCHE'!J5 -> Plutôt Bon | C12: Marché régional ou zone géographique diversifiée et parts de marché faibles
A13: 5 | B13: ='GRILLE SOUCHE'!K5 -> Moyen | C13: Marché local/National et parts de marché significatives
A14: 6 | B14: ='GRILLE SOUCHE'!L5 -> Plutôt Moyen | C14: Marché local/National et parts de marché importantes
A15: 7 | B15: ='GRILLE SOUCHE'!M5 -> Faible | C15: Marché local ou zone géographique peu diversifiée et parts de marché moyennes
A16: 8 | B16: ='GRILLE SOUCHE'!N5 -> Limité | C16: Marché local ou zone géographique peu diversifiée et parts de marché faibles
A17: 9 | B17: ='GRILLE SOUCHE'!O5 -> Mauvais | C17: Marché local non diversifié et parts de marché faibles
A18: 10 | B18: ='GRILLE SOUCHE'!P5 -> Très Mauvais | C18: Marché étroit et parts de marché faibles

Sheet DEFINITION DES NOTES
A1: Note moyenne des critères et sous-critères d'analyse
A2: Définitions générales
A3: SME1 Excellent Situation économique et financière et visibilité excellentes : forte position sur ses marchés, faible endettement par rapport aux fonds propres et au cash flow, peu sensible aux aléas conjoncturels (grande stabilité de la situation financière et des résultats à travers les cycles de son industrie et de l'économie en général). Sa taille et sa situation lui donnent un accès très facile aux marchés financiers. La capacité du débiteur à exécuter ses engagements financiers est TRES FORTE | C3: SME6 Acceptable Les risques sectoriels, financiers et économiques sont importants mais devraient être compensés par les fondamentaux du débiteur. Possibilité limitée de trouver des financements en dehors de ses banques. La qualité du management est un élément important de la décision. Les opérations doivent être structurées (garanties, covenants) pour limiter le risque et la rémunération doit être accrue pour tenir compte de la prime de risque plus élevée.
A5: SME2 Très Bon La situation financière et le niveau de cash flow actuels sont très bons, avec un historique montrant une bonne stabilité, mais avec une légère sensibilité aux aléas conjoncturels. Endettement modéré par rapport aux fonds propres et au cash flow. Solide position sur ses marchés. Très bonne visibilité à court et moyen terme. Accès facile aux marchés financiers. Sa capacité à exécuter ses engagements financiers est FORTE. | C5: SME7 Potentiellement vulnérable Endettement important pour le secteur. Les risques sectoriels, financiers et économiques sont importants et insuffisamment compensés par les fondamentaux du débiteur qui ne présentent pas une qualité, une stabilité et une visibilité suffisantes. Ce niveau nécessite un suivi attentif. La qualité du management est un élément primordial de la décision. Ce niveau nécessite une grande exigence dans la structuration des opérations et une rémunération significative.
A7: SME3 Bon Situation financière et cash flow convenables mais montrant quelque volatilité, et qui pourraient être affaiblis par une conjoncture (cycle) ou des évènements défavorables dont l'occurrence est possible. Endettement par rapport aux fonds propres et au cash flow dans la moyenne. Bonne visibilité à court et moyen terme. Possibilité d'accéder à de nouveaux financements dans une conjoncture normale. Cette note s'applique aussi aux PME dont la situation financière est solide mais qui sont exclues des catégories précédentes en raison de leur taille. | C7: SME7- Vulnérable Une aggravation des risques économiques et financiers qui pèsent sur le débiteur le conduirait vraisemblablement à faire défaut sur ses engagements financiers. De nouvelles opérations ne peuvent être envisagées qu'avec une extrême rigueur dans la structuration et uniquement dans le cadre de politiques de crédit dûment autorisées.
A9: SME4 Assez Bon Situation financière et cash flow moyens, avec une plus grande volatilité de la situation financière et du cash flow. Il existe quelques facteurs de risque qui pourraient affaiblir la capacité du débiteur à exécuter ses engagements financiers. Cependant, visibilité satisfaisante à court et moyen terme. Accès restreint aux marchés financiers et plus coûteux, mais possibilité de développement des engagements avec ses banques. | C9: SME8 Très vulnérable En l'absence d'amélioration de l'environnement (conjoncture et marché), et/ou de mesures drastiques de restructuration industrielle ou financière, la survie de l'entreprise serait en question. Ce niveau doit être suivi de près et assorti d'objectifs précis pour réduire les risques (réduction des concours, garanties, etc.). Normalement, il exclut une entrée en relation ou un accroissement des engagements.
A11: SME5 Moyen Cash flow suffisant pour le service de la dette. Les incertitudes sur les fondamentaux du débiteur et son exposition à divers risques (sectoriels, financiers, économiques) peuvent affecter à terme sa capacité à s'acquitter de ses obligations. Visibilité satisfaisante à court terme mais moins claire à moyen terme. Un accroissement des engagements auprès de ses banques reste encore envisageable. La qualité du management est un élément important de la décision. Accès aux marchés financiers limité, restreint et plus coûteux. | C11: SME8- Douteux et/ou compromis L'existence d'échéances financières impayées en principal et/ou en intérêts depuis plus de 3 mois entraîne le classement dans cette catégorie. Les débiteurs les plus faibles de cette catégorie sont dans une situation nettement dégradée et préoccupante quant à la bonne fin des crédits. Un dépôt de bilan est fortement possible. Ce niveau doit être suivi de très près. Le suivi doit être assortie d'objectifs précis (réduction des concours, amélioration des garanties, etc.). La gestion doit être centralisée (prise en charge par les équipes spécialisées dans la prévention de la défaillance).

Sheet NOTATION ELESYST DES PME
A1: Notation conventionnelle des PME adoptée par ELESYST
A2: Définitions générales
A4: SAVSME CMR SME1 Le niveau de solvabilité de la PME, validé en comparaison d'autres PME, est très élevé
A6: SAVSME CMR SME2 Le niveau de solvabilité de la PME, validé en comparaison d'autres PME, est élevé
A8: SAVSME CMR SME3 Le niveau de solvabilité de la PME, validé en comparaison d'autres PME, est au dessus de la moyenne
A10: SAVSME CMR SME4 Le niveau de solvabilité de la PME, validé en comparaison d'autres PME, est moyen
A12: SAVSME CMR SME5 Le niveau de solvabilité de la PME, validé en comparaison d'autres PME, est en dessous de la moyenne
A14: SAVSME CMR SME6 Le niveau de solvabilité de la PME, validé en comparaison d'autres PME, est insuffisant
A16: SAVSME CMR SME7 Le niveau de solvabilité de la PME, validé en comparaison d'autres PME, est bas
A18: SAVSME CMR SME8 Le niveau de solvabilité de la PME, validé en comparaison d'autres PME, est très bas. La PME présente un risque important de défaut.

Sheet COMMENTAIRES annexes
A1: Nom de la société: Secteur d'activité: Nom du Dirigeant:
A2: Effectif employés: Année de création:
A3: CRITERES | B3: N° SOUS-CRITERES | C3: SOUS-CRITERES | D3: COMMENTAIRES
A4: ACTIVITE | B4: 1 | C4: Positionnement concurentiel sur le marché | D4: Permet d'apprécier le pouvoir de négociation de l'entreprise sur les marchés, les parts de marchés acquises, et sa capacité à innover.
B5: 2 | C5: Tendance structurelle du marché | D5: Renvoie à l’évolution du marché sur lequel l’entreprise se situe (croissance, stagnation, déclin) et de ce fait sa capacité à développer son activité.
B6: 3 | C6: Marchés cycliques ou à prix volatils | D6: Les marchés cycliques sont caractérisés par des périodes de croissance suivies de repli plus ou moins prononcées et plus ou moins rapprochées. Les marchés à prix volatils sont ceux liés aux matières premières dont les prix sont sujets à de fortes variations.
B7: 4 | C7: Portefeuille produit | D7: Ce critère permet de porter un jugement sur la capacité de l’entreprise à diversifier et adapter son offre de produits sur le marché. Il s'agit d'évaluer son niveau de maitrise de sa politique de gestion du cycle de vie de ses produits (Matrice BCG).
B8: 5 | C8: Pression liée à la clientèle | D8: Appreciation du risque lié à la pression de la clientèle directe de l'entreprise (client représentant 10% de son CA) : diversifiée ou concentrée, fidélisée ou non récurrente, rapport de force de bonne ou mauvaise qualité.
B9: 6 | C9: Barrière à l'entrée | D9: Ensemble des inerties qui peuvent constituer un frein à la création ou à l'exercice de l'activité de l'entreprises.
B10: 7 | C10: Visibilité du secteur | D10: Tenir compte des changements possible de la réglementation, de la qualité de l'environnement du pays dans lequel l'entreprise opère (viabilité du système législatif, qualité du système politique, environnement social)
A11: GESTION & STRATEGIE | B11: 8 | C11: Qualité du profil du drigeant | D11: L’expérience des promoteurs dans les affaires (dans un secteur d’activité représentatif) et l’historique des opérations de l’entité étudiée constituent des critères essentiels pour évaluer la compétence managériale. Un manager doté d’une expérience de plusieurs cycles d’activités et familiarisé à la mise en œuvre des projets, bénéficie d’un avantage certain. De même, l’expérience dans la conquête de la clientèle, les nouvelles initiatives commerciales et le niveau de priorité accordé à la fonction financière sont également des critères vitaux. Un poids conséquent doit être accordé à l’historique du promoteur dans la réalisation des projets et le statut desdits projets, incluant la réussite du montage financier. Enfin le profil moral des dirigeants doit être systématiquement questionné en intégrant des critères socio-anthropologiques liés aux différents réseaux sociaux et professionnels avec lesquels ils interagissent.
B12: 9 | C12: Qualité de l'organisation | D12: La maîtrise des processus métiers et administratifs de l'entité doit être matérialisée à travers les procédures et les textes organiques couvrant tous les pans fonctionnels. Au-delà de l'existence de ces textes, il est important de vérifier qu'ils sont connus et mis en application par les principaux responsables et l'ensemble du personnel.
B13: 10 | C13: Qualité du système de contrôle interne | D13: Il s'agit d'apprecier l'organisation des ressources qui permettent de collecter, stocker, traiter et distribuer les informations nécessaires à une prise de décisions , le suivi et le contrôle des activité de l'entreprise.
B14: 11 | C14: Qualité de la Stratégie commerciale et marketing | D14: Ce critère permet d'évaluer les actions menées par l'entreprise afin de d'accroître ses parts de marché et donc par conséquent developper son portefeuille client.
B15: 12 | C15: Qualité des Moyens humains et techniques | D15: Appréciation de la stratégie en terme de clarté et de pérénnité de l'entreprise, de cohérence entre qualité des investisssements, corps de metiers identifiés, perspectives de marché et action des concurrents.
B16: 13 | C16: Adéquation des investissements / Impact sur l'emploi | D16: Apprecier si les investissements consentis par l'entreprise permettent de réaliser en quantité et en qualité les biens et services souhaités par cette dernière et si l'impact sur la création et la préservation des emplois est positif.
B17: 14 | C17: Maîtrise des coûts de productivité / Impact sur la création des richesses | D17: Evaluer la capacité de l'entreprise à minimiser ses coûts de production tout en réalisant des gains supplémentaires. Apprécier sa capacité à créer des richesses nouvelles.
B18: 15 | C18: Cohérence des options stratégiques / Impact sur l'environnement | D18: Il importe qu'à la création d'une entreprise ou au début de chaque nouvel exercice, de s'assurer de la cohérence des décisions stratégiques prises par les dirigeants concernant : l'activité, les moyens de production, les ressources humaines et les finances. Une inadéquation entre ces décisions constitue une source importante de risque de pertes pour l'entreprise. L'impact environnemental des options stratégiques retenues doit influencer l'évaluation.
B19: 16 | C19: Qualité des relations sociales | D19: Appreciation du climat social, de la politique de gestion des ressources humaine, du niveau de turn-over du personnel. Des entretiens avec toutes les catégories du personnel sont indispensables pour cerner la qualité du climat.
B20: 17 | C20: Succession des Dirigeants | D20: Il s'agit d'évaluer dans quelle mesure le risque lié aux droits de succession est encadré au sein de l'entreprise, ce qui permet d'assurer la pérénité de son patrimoine.
A21: FINANCES | B21: 18 | C21: Dynamique de l'équilibre financier (FR / BFR >= 1) | D21: Elle permet d'apprécier l'évolution de l'équilibre financier dans le temps (la situation d'équilibre financier étant la couverture de l'ensemble des besoin liés à l'exploitation par le fond de roulement). Un ratio de structure financière de 0,5 est considéré comme acceptable. Cela signifie que le FR couvre au moins la moitié du BFR.
B22: 19 | C22: Ratio d'endettement global ((Actifs - Capitaux propres)/ Actifs) <1 | D22: Il permet d'apprécier la niveau de d'endettement de l'entreprise et sa soutenntabilité. Il compare la dette d’une entreprise à ses actifs, ce qui donne alors une idée du levier qu’utilise cette dernière pour fonctionner. Il est égal à : (Actifs - Capitaux propres) / Actifs Un ratio faible traduit une faible dépendance à l’égard de la dette, autrement dit, l’entreprise n’a pas un besoin vital de faire appel aux capitaux d’agents extérieurs (banques) pour opérer. Plus le ratio est faible, plus l’entreprise fait appel à ses propres capitaux pour fonctionner (autofinancement). Plus le ratio est élevé, plus l’entreprise a une comptabilité risquée. Si un ratio démesurément élevé peut mettre en péril la solvabilité de l’entreprise, il peut également masquer un sous-investissement de celle-ci, et donc, un potentiel décrochage en termes de compétitivité. Un ratio d’endettement de 0,50 est considéré comme acceptable. Cela signifie que l’entreprise possède deux fois plus d’actifs que de dettes. Ou, exprimé différemment, les dettes ne représentent que la moitié des actifs. En d’autres termes, les créditeurs de l’entreprise possèdent la moitié des actifs de celle-ci, tandis que les actionnaires détiennent l’autre moitié.
B23: 20 | C23: Capacité de remboursement (DLMT/ CAFG) < 3 | D23: Il exprime la disposition de l'entreprise à rembourser son endettement net au moyen de sa capacité d'autofinancement. Il permet de mesurer le nombre d'années de CAFG necessaire à l'entreprise pour rembourser, par ses propres moyens, la totalité de ses dettes. Un ratio de capacité de remboursement de 3 est considéré comme acceptable.
B24: 21 | C24: Couverture des frais financiers (FTAO/FF)> 3 | D24: Ce ratio est exprimé en un chiffre, qui indique combien de fois les intérêts sont couverts par les flux de trésorerie des activités ordinaires. Un ratio de couverture inférieur à 3 signale que la marge de sécurité de l'entreprise est insuffisante. Un ratio égal à 3 est considéré comme un minimum. Il permet d'évaluer la capacité de l'entreprise à rembourser les charges financières à partir de ses ressources d'exploitation.
B25: 22 | C25: Solvabilité globale - Risque liquidatif (Ressources Propres/Total Bilan) > 25% | D25: C'est la mesure de la solvabilité globale de l'affaire : les ressources propres doivent être suffisantes pour supporter une certaine dévalorisation de l'actif tel qu'il figure au bilan. La comparaison du niveau des ressources propres par rapport au total du bilan est une mesure du degré d'engagement des actionnaires dans le risque d'entreprise. On considère que ce ratio doit excéder les 25% pour que l'entreprise ne soit pas trop endettée, on majorera ce chiffre pour le secteur industriel (35%) et on le minorera pour le secteur commercial (20%). Ce ratio mesure aussi, du point de vue des tiers à l'entreprise - hors associés et prêteurs - quelle dépréciation moyenne peut supporter l'actif avant que ces tiers ne soient amenés à assumer eux mêmes le risque d'entreprise.
B26: 23 | C26: Liquidité générale (Ratio de FR= Actifs circulants/ Passifs circulants)>1 | D26: Assimilable au fonds de roulement, ce ratio permet de savoir si une entreprise est capable d’assumer (ou pas) ses dettes à court terme en les mettant au regard de ses actifs à court terme. Ce ratio doit toujours être supérieur à 1. Plus il est élevé, plus la latitude dont dispose une société pour développer ses activités est grande. Sauf circonstances particulières, un ratio inférieur à 1 signifie que le fonds de roulement est négatif.
B27: 24 | C27: Rentabilité d'exploitation par rapport au CA (EBE/ CA)>30% | D27: Il permet d'apprecier la capacité de l'exploitation à dégager un revenu satisfaisant après couverture des charges directement liées à l'activité. L'EBE est indispensable pour apprécier la performance d’une société car il permet de mesurer les bénéfices et profits réalisés dans l’entreprise. Il est également très utilisé car n’étant pas affecté par la politique d’amortissement et de provision de l’entreprise. En anglais, on parle de Earnings Before Interest, Taxes, Depreciation and Amortization (EBITDA). Formule : Excédent Brut d'Exploitation = valeur ajoutée brute - frais du personnel (salaires + cotisations sociales) - impôts et taxes liés à la production (- participation des salariés, pour obtenir l’EBITDA) Le ratio EBE/CA, appelé marge d’EBE, permet d’apprécier le partage de la valeur ajoutée entre les actionnaires (qui sont rémunérés à partir de l'Excédent brut d'exploitation) et les salariés.
B28: 25 | C28: Rentabilité économique ou Return On Capital Employed (ROCE) (Résultat d'Exploitation / Total actifs) > 10% | D28: Permet d'apprecier le comportement de la rentabilité comparativement aux investissements de toute nature necessaires à l'exploitation de l'entreprise. C’est un ratio fondamental de l’analyse financière. Il représente l’efficacité avec laquelle l’entreprise utilise les capitaux mis à sa disposition et n’est pas affecté par la structure financière de l’entreprise. Le principal inconvénient de ce ratio est qu’il prend en compte la valeur comptable d’actifs qui se déprécient, alors que le résultat d’exploitation a tendance à croître avec l’inflation. Dans le cadre d’une comparaison d’entreprises ayant la même activité, les actifs les plus dépréciés auront une ROCE plus élevée, même si les actifs les plus récents sont peut-être plus efficaces. Un ratio de rentabilité économique de 10% est considéré comme acceptable.
